<?xml version="1.0"?>
<robot name="my_robot" xmlns:xacro="http://www.ros.org/wiki/xacro">

  <link name="base_link">
<inertial>
      <origin xyz="0 0 0" rpy="0 0 0"/>
      <mass value="1.0" />
      <inertia ixx="0.0741666666667" ixy="0.0" ixz="0.0" iyy="0.0585416666667" iyz="0.0" izz="0.0260416666667"/>
</inertial>
    <collision name="base_link_collision">
      <geometry>
        <cylinder length="0" radius="0"/>
      </geometry>
    </collision>
    <visual>
      <geometry>
        <cylinder radius="0.5" length="0.2" />
      </geometry>
    </visual>
  </link>

  <!-- Define left wheel -->
  <joint name="left_wheel_joint" type="continuous">
    <parent link="base_link" />
    <child link="left_wheel_link" />
    <origin xyz="0 0 0" rpy="0 0 0" />
    <axis xyz="0 0 1" />
	<origin rpy="0 -1.5708 0" xyz="-0.275 0 0"/>
	<inertial>
	<mass value="1.0"/>
	<inertia ixx="5.1458e-5" iyy="5.1458e-5" izz="5.1458e-5" ixy="0" ixz="0" iyz="0"/>
	</inertial>
  </joint>

  <link name="left_wheel_link">
<inertial>
      <origin xyz="0 0 0" rpy="0 0 0"/>
      <mass value="1.0" />
      <inertia ixx="0.0741666666667" ixy="0.0" ixz="0.0" iyy="0.0585416666667" iyz="0.0" izz="0.0260416666667"/>
</inertial>
<visual>
    <geometry>
        <cylinder length="0.05" radius="0.05"/>
    </geometry>
    <material name="black"/>            
</visual>
<collision>
    <geometry>
        <cylinder length="0.05" radius="0.05"/>
    </geometry>
</collision>
  </link>

<!-- 
  <joint name="right_wheel_joint" type="continuous">
    <parent link="base_link" />
    <child link="right_wheel_link" />
    <origin xyz="0 0 0" rpy="0 0 0" />
    <axis xyz="0 0 1" />
  </joint>

  <link name="right_wheel_link">
    <inertial>
      <mass value="0.5" />
      <origin xyz="0 0 0" />
      <inertia ixx="0.001" ixy="0.0" ixz="0.0" iyy="0.001" iyz="0.0" izz="0.001" />
    </inertial>
    <visual>
      <origin xyz="-0.05 0 0" rpy="0 0 0" />
      <geometry>
        <cylinder radius="0.025" length="0.05" />
      </geometry>
      <material name="red">
        <color rgba="1 0 0 1" />
      </material>
    </visual>
  </link> 
  -->
  
  
</robot>

